<?xml version="1.0" encoding="UTF-8"?>
<!-- Generated by org.testng.reporters.JUnitReportReporter -->
<testsuite hostname="Rahul-Dev-Ghosh" failures="2" tests="12" name="com.salesforce.qa.testcases.LoginPageTest" time="74.338" errors="0" timestamp="2022-05-14T14:36:03 IST" skipped="0">
  <testcase classname="com.salesforce.qa.testcases.LoginPageTest" name="validateLoginNegativeScenarios" time="5.561"/>
  <system-out/>
  <testcase classname="com.salesforce.qa.testcases.LoginPageTest" name="validateLoginNegativeScenarios" time="13.567">
    <failure message="The following asserts failed:
	did not expect [Home | Salesforce] but found [Home | Salesforce]" type="java.lang.AssertionError">
      <![CDATA[java.lang.AssertionError: The following asserts failed:
did not expect [Home | Salesforce] but found [Home | Salesforce]
at org.testng.asserts.SoftAssert.assertAll(SoftAssert.java:46)
at org.testng.asserts.SoftAssert.assertAll(SoftAssert.java:30)
at com.salesforce.qa.testcases.LoginPageTest.validateLoginNegativeScenarios(LoginPageTest.java:60)
at java.base/jdk.internal.reflect.NativeMethodAccessorImpl.invoke0(Native Method)
at java.base/jdk.internal.reflect.NativeMethodAccessorImpl.invoke(NativeMethodAccessorImpl.java:62)
at java.base/jdk.internal.reflect.DelegatingMethodAccessorImpl.invoke(DelegatingMethodAccessorImpl.java:43)
at java.base/java.lang.reflect.Method.invoke(Method.java:566)
at org.testng.internal.invokers.MethodInvocationHelper.invokeMethod(MethodInvocationHelper.java:135)
at org.testng.internal.invokers.TestInvoker.invokeMethod(TestInvoker.java:673)
at org.testng.internal.invokers.TestInvoker.invokeTestMethod(TestInvoker.java:220)
at org.testng.internal.invokers.MethodRunner.runInSequence(MethodRunner.java:50)
at org.testng.internal.invokers.TestInvoker$MethodInvocationAgent.invoke(TestInvoker.java:945)
at org.testng.internal.invokers.TestInvoker.invokeTestMethods(TestInvoker.java:193)
at org.testng.internal.invokers.TestMethodWorker.invokeTestMethods(TestMethodWorker.java:146)
at org.testng.internal.invokers.TestMethodWorker.run(TestMethodWorker.java:128)
at java.base/java.util.ArrayList.forEach(ArrayList.java:1541)
at org.testng.TestRunner.privateRun(TestRunner.java:808)
at org.testng.TestRunner.run(TestRunner.java:603)
at org.testng.SuiteRunner.runTest(SuiteRunner.java:429)
at org.testng.SuiteRunner.runSequentially(SuiteRunner.java:423)
at org.testng.SuiteRunner.privateRun(SuiteRunner.java:383)
at org.testng.SuiteRunner.run(SuiteRunner.java:326)
at org.testng.SuiteRunnerWorker.runSuite(SuiteRunnerWorker.java:52)
at org.testng.SuiteRunnerWorker.run(SuiteRunnerWorker.java:95)
at org.testng.TestNG.runSuitesSequentially(TestNG.java:1249)
at org.testng.TestNG.runSuitesLocally(TestNG.java:1169)
at org.testng.TestNG.runSuites(TestNG.java:1092)
at org.testng.TestNG.run(TestNG.java:1060)
at org.testng.remote.AbstractRemoteTestNG.run(AbstractRemoteTestNG.java:115)
at org.testng.remote.RemoteTestNG.initAndRun(RemoteTestNG.java:251)
at org.testng.remote.RemoteTestNG.main(RemoteTestNG.java:77)
]]>
    </failure>
  </testcase> <!-- validateLoginNegativeScenarios -->
  <system-out/>
  <testcase classname="com.salesforce.qa.testcases.LoginPageTest" name="validateLoginNegativeScenarios" time="3.911"/>
  <system-out/>
  <testcase classname="com.salesforce.qa.testcases.LoginPageTest" name="validateLoginNegativeScenarios" time="4.856"/>
  <system-out/>
  <testcase classname="com.salesforce.qa.testcases.LoginPageTest" name="loginPageLogoTest" time="3.271"/>
  <system-out/>
  <testcase classname="com.salesforce.qa.testcases.LoginPageTest" name="loginPageTitleTest" time="3.389"/>
  <system-out/>
  <testcase classname="com.salesforce.qa.testcases.LoginPageTest" name="validateLoginNegativeScenarios" time="3.377"/>
  <system-out/>
  <testcase classname="com.salesforce.qa.testcases.LoginPageTest" name="validateLoginNegativeScenarios" time="11.122"/>
  <system-out/>
  <testcase classname="com.salesforce.qa.testcases.LoginPageTest" name="validateLogin" time="12.497">
    <failure message="expected [Home | Salesforce] but found [Lightning Experience]" type="java.lang.AssertionError">
      <![CDATA[java.lang.AssertionError: expected [Home | Salesforce] but found [Lightning Experience]
at org.testng.Assert.fail(Assert.java:110)
at org.testng.Assert.failNotEquals(Assert.java:1413)
at org.testng.Assert.assertEqualsImpl(Assert.java:149)
at org.testng.Assert.assertEquals(Assert.java:131)
at org.testng.Assert.assertEquals(Assert.java:655)
at org.testng.Assert.assertEquals(Assert.java:665)
at com.salesforce.qa.testcases.LoginPageTest.validateLogin(LoginPageTest.java:51)
at java.base/jdk.internal.reflect.NativeMethodAccessorImpl.invoke0(Native Method)
at java.base/jdk.internal.reflect.NativeMethodAccessorImpl.invoke(NativeMethodAccessorImpl.java:62)
at java.base/jdk.internal.reflect.DelegatingMethodAccessorImpl.invoke(DelegatingMethodAccessorImpl.java:43)
at java.base/java.lang.reflect.Method.invoke(Method.java:566)
at org.testng.internal.invokers.MethodInvocationHelper.invokeMethod(MethodInvocationHelper.java:135)
at org.testng.internal.invokers.TestInvoker.invokeMethod(TestInvoker.java:673)
at org.testng.internal.invokers.TestInvoker.invokeTestMethod(TestInvoker.java:220)
at org.testng.internal.invokers.MethodRunner.runInSequence(MethodRunner.java:50)
at org.testng.internal.invokers.TestInvoker$MethodInvocationAgent.invoke(TestInvoker.java:945)
at org.testng.internal.invokers.TestInvoker.invokeTestMethods(TestInvoker.java:193)
at org.testng.internal.invokers.TestMethodWorker.invokeTestMethods(TestMethodWorker.java:146)
at org.testng.internal.invokers.TestMethodWorker.run(TestMethodWorker.java:128)
at java.base/java.util.ArrayList.forEach(ArrayList.java:1541)
at org.testng.TestRunner.privateRun(TestRunner.java:808)
at org.testng.TestRunner.run(TestRunner.java:603)
at org.testng.SuiteRunner.runTest(SuiteRunner.java:429)
at org.testng.SuiteRunner.runSequentially(SuiteRunner.java:423)
at org.testng.SuiteRunner.privateRun(SuiteRunner.java:383)
at org.testng.SuiteRunner.run(SuiteRunner.java:326)
at org.testng.SuiteRunnerWorker.runSuite(SuiteRunnerWorker.java:52)
at org.testng.SuiteRunnerWorker.run(SuiteRunnerWorker.java:95)
at org.testng.TestNG.runSuitesSequentially(TestNG.java:1249)
at org.testng.TestNG.runSuitesLocally(TestNG.java:1169)
at org.testng.TestNG.runSuites(TestNG.java:1092)
at org.testng.TestNG.run(TestNG.java:1060)
at org.testng.remote.AbstractRemoteTestNG.run(AbstractRemoteTestNG.java:115)
at org.testng.remote.RemoteTestNG.initAndRun(RemoteTestNG.java:251)
at org.testng.remote.RemoteTestNG.main(RemoteTestNG.java:77)
]]>
    </failure>
  </testcase> <!-- validateLogin -->
  <system-out/>
  <testcase classname="com.salesforce.qa.testcases.LoginPageTest" name="validateLoginNegativeScenarios" time="3.794"/>
  <system-out/>
  <testcase classname="com.salesforce.qa.testcases.LoginPageTest" name="validateLoginNegativeScenarios" time="4.080"/>
  <system-out/>
  <testcase classname="com.salesforce.qa.testcases.LoginPageTest" name="validateLoginNegativeScenarios" time="4.913"/>
  <system-out/>
</testsuite> <!-- com.salesforce.qa.testcases.LoginPageTest -->
